2017-05-01 01:18:12,236 INFO: microblog startup [in /home/minas/microblog/app/__init__.py:24]
2017-05-01 01:21:54,286 INFO: microblog startup [in /home/minas/microblog/app/__init__.py:24]
2017-05-01 01:30:22,131 INFO: microblog startup [in /home/minas/microblog/app/__init__.py:24]
2017-05-01 01:30:42,178 ERROR: Exception on /login [GET] [in /home/minas/microblog/flask/lib/python3.5/site-packages/flask/app.py:1560]
Traceback (most recent call last):
  File "/home/minas/microblog/flask/lib/python3.5/site-packages/sqlalchemy/engine/base.py", line 1182, in _execute_context
    context)
  File "/home/minas/microblog/flask/lib/python3.5/site-packages/sqlalchemy/engine/default.py", line 470, in do_execute
    cursor.execute(statement, parameters)
sqlite3.IntegrityError: UNIQUE constraint failed: user.nickname

The above exception was the direct cause of the following exception:

Traceback (most recent call last):
  File "/home/minas/microblog/flask/lib/python3.5/site-packages/flask/app.py", line 1982, in wsgi_app
    response = self.full_dispatch_request()
  File "/home/minas/microblog/flask/lib/python3.5/site-packages/flask/app.py", line 1614, in full_dispatch_request
    rv = self.handle_user_exception(e)
  File "/home/minas/microblog/flask/lib/python3.5/site-packages/flask/app.py", line 1517, in handle_user_exception
    reraise(exc_type, exc_value, tb)
  File "/home/minas/microblog/flask/lib/python3.5/site-packages/flask/_compat.py", line 33, in reraise
    raise value
  File "/home/minas/microblog/flask/lib/python3.5/site-packages/flask/app.py", line 1612, in full_dispatch_request
    rv = self.dispatch_request()
  File "/home/minas/microblog/flask/lib/python3.5/site-packages/flask/app.py", line 1598, in dispatch_request
    return self.view_functions[rule.endpoint](**req.view_args)
  File "/home/minas/microblog/flask/lib/python3.5/site-packages/flask_openid.py", line 507, in decorated
    openid_response, self.extension_responses))
  File "/home/minas/microblog/app/views.py", line 67, in after_login
    db.session.commit()
  File "/home/minas/microblog/flask/lib/python3.5/site-packages/sqlalchemy/orm/scoping.py", line 157, in do
    return getattr(self.registry(), name)(*args, **kwargs)
  File "/home/minas/microblog/flask/lib/python3.5/site-packages/sqlalchemy/orm/session.py", line 874, in commit
    self.transaction.commit()
  File "/home/minas/microblog/flask/lib/python3.5/site-packages/sqlalchemy/orm/session.py", line 461, in commit
    self._prepare_impl()
  File "/home/minas/microblog/flask/lib/python3.5/site-packages/sqlalchemy/orm/session.py", line 441, in _prepare_impl
    self.session.flush()
  File "/home/minas/microblog/flask/lib/python3.5/site-packages/sqlalchemy/orm/session.py", line 2139, in flush
    self._flush(objects)
  File "/home/minas/microblog/flask/lib/python3.5/site-packages/sqlalchemy/orm/session.py", line 2259, in _flush
    transaction.rollback(_capture_exception=True)
  File "/home/minas/microblog/flask/lib/python3.5/site-packages/sqlalchemy/util/langhelpers.py", line 66, in __exit__
    compat.reraise(exc_type, exc_value, exc_tb)
  File "/home/minas/microblog/flask/lib/python3.5/site-packages/sqlalchemy/util/compat.py", line 187, in reraise
    raise value
  File "/home/minas/microblog/flask/lib/python3.5/site-packages/sqlalchemy/orm/session.py", line 2223, in _flush
    flush_context.execute()
  File "/home/minas/microblog/flask/lib/python3.5/site-packages/sqlalchemy/orm/unitofwork.py", line 389, in execute
    rec.execute(self)
  File "/home/minas/microblog/flask/lib/python3.5/site-packages/sqlalchemy/orm/unitofwork.py", line 548, in execute
    uow
  File "/home/minas/microblog/flask/lib/python3.5/site-packages/sqlalchemy/orm/persistence.py", line 181, in save_obj
    mapper, table, insert)
  File "/home/minas/microblog/flask/lib/python3.5/site-packages/sqlalchemy/orm/persistence.py", line 835, in _emit_insert_statements
    execute(statement, params)
  File "/home/minas/microblog/flask/lib/python3.5/site-packages/sqlalchemy/engine/base.py", line 945, in execute
    return meth(self, multiparams, params)
  File "/home/minas/microblog/flask/lib/python3.5/site-packages/sqlalchemy/sql/elements.py", line 263, in _execute_on_connection
    return connection._execute_clauseelement(self, multiparams, params)
  File "/home/minas/microblog/flask/lib/python3.5/site-packages/sqlalchemy/engine/base.py", line 1053, in _execute_clauseelement
    compiled_sql, distilled_params
  File "/home/minas/microblog/flask/lib/python3.5/site-packages/sqlalchemy/engine/base.py", line 1189, in _execute_context
    context)
  File "/home/minas/microblog/flask/lib/python3.5/site-packages/sqlalchemy/engine/base.py", line 1402, in _handle_dbapi_exception
    exc_info
  File "/home/minas/microblog/flask/lib/python3.5/site-packages/sqlalchemy/util/compat.py", line 203, in raise_from_cause
    reraise(type(exception), exception, tb=exc_tb, cause=cause)
  File "/home/minas/microblog/flask/lib/python3.5/site-packages/sqlalchemy/util/compat.py", line 186, in reraise
    raise value.with_traceback(tb)
  File "/home/minas/microblog/flask/lib/python3.5/site-packages/sqlalchemy/engine/base.py", line 1182, in _execute_context
    context)
  File "/home/minas/microblog/flask/lib/python3.5/site-packages/sqlalchemy/engine/default.py", line 470, in do_execute
    cursor.execute(statement, parameters)
sqlalchemy.exc.IntegrityError: (sqlite3.IntegrityError) UNIQUE constraint failed: user.nickname [SQL: 'INSERT INTO user (nickname, email, about_me, last_seen) VALUES (?, ?, ?, ?)'] [parameters: ('Minas', 'migr94migr@yahoo.com', None, None)]
2017-05-01 01:39:43,311 ERROR: Exception on /login [GET] [in /home/minas/microblog/flask/lib/python3.5/site-packages/flask/app.py:1560]
Traceback (most recent call last):
  File "/home/minas/microblog/flask/lib/python3.5/site-packages/sqlalchemy/engine/base.py", line 1182, in _execute_context
    context)
  File "/home/minas/microblog/flask/lib/python3.5/site-packages/sqlalchemy/engine/default.py", line 470, in do_execute
    cursor.execute(statement, parameters)
sqlite3.IntegrityError: UNIQUE constraint failed: user.nickname

The above exception was the direct cause of the following exception:

Traceback (most recent call last):
  File "/home/minas/microblog/flask/lib/python3.5/site-packages/flask/app.py", line 1982, in wsgi_app
    response = self.full_dispatch_request()
  File "/home/minas/microblog/flask/lib/python3.5/site-packages/flask/app.py", line 1614, in full_dispatch_request
    rv = self.handle_user_exception(e)
  File "/home/minas/microblog/flask/lib/python3.5/site-packages/flask/app.py", line 1517, in handle_user_exception
    reraise(exc_type, exc_value, tb)
  File "/home/minas/microblog/flask/lib/python3.5/site-packages/flask/_compat.py", line 33, in reraise
    raise value
  File "/home/minas/microblog/flask/lib/python3.5/site-packages/flask/app.py", line 1612, in full_dispatch_request
    rv = self.dispatch_request()
  File "/home/minas/microblog/flask/lib/python3.5/site-packages/flask/app.py", line 1598, in dispatch_request
    return self.view_functions[rule.endpoint](**req.view_args)
  File "/home/minas/microblog/flask/lib/python3.5/site-packages/flask_openid.py", line 507, in decorated
    openid_response, self.extension_responses))
  File "/home/minas/microblog/app/views.py", line 67, in after_login
    db.session.commit()
  File "/home/minas/microblog/flask/lib/python3.5/site-packages/sqlalchemy/orm/scoping.py", line 157, in do
    return getattr(self.registry(), name)(*args, **kwargs)
  File "/home/minas/microblog/flask/lib/python3.5/site-packages/sqlalchemy/orm/session.py", line 874, in commit
    self.transaction.commit()
  File "/home/minas/microblog/flask/lib/python3.5/site-packages/sqlalchemy/orm/session.py", line 461, in commit
    self._prepare_impl()
  File "/home/minas/microblog/flask/lib/python3.5/site-packages/sqlalchemy/orm/session.py", line 441, in _prepare_impl
    self.session.flush()
  File "/home/minas/microblog/flask/lib/python3.5/site-packages/sqlalchemy/orm/session.py", line 2139, in flush
    self._flush(objects)
  File "/home/minas/microblog/flask/lib/python3.5/site-packages/sqlalchemy/orm/session.py", line 2259, in _flush
    transaction.rollback(_capture_exception=True)
  File "/home/minas/microblog/flask/lib/python3.5/site-packages/sqlalchemy/util/langhelpers.py", line 66, in __exit__
    compat.reraise(exc_type, exc_value, exc_tb)
  File "/home/minas/microblog/flask/lib/python3.5/site-packages/sqlalchemy/util/compat.py", line 187, in reraise
    raise value
  File "/home/minas/microblog/flask/lib/python3.5/site-packages/sqlalchemy/orm/session.py", line 2223, in _flush
    flush_context.execute()
  File "/home/minas/microblog/flask/lib/python3.5/site-packages/sqlalchemy/orm/unitofwork.py", line 389, in execute
    rec.execute(self)
  File "/home/minas/microblog/flask/lib/python3.5/site-packages/sqlalchemy/orm/unitofwork.py", line 548, in execute
    uow
  File "/home/minas/microblog/flask/lib/python3.5/site-packages/sqlalchemy/orm/persistence.py", line 181, in save_obj
    mapper, table, insert)
  File "/home/minas/microblog/flask/lib/python3.5/site-packages/sqlalchemy/orm/persistence.py", line 835, in _emit_insert_statements
    execute(statement, params)
  File "/home/minas/microblog/flask/lib/python3.5/site-packages/sqlalchemy/engine/base.py", line 945, in execute
    return meth(self, multiparams, params)
  File "/home/minas/microblog/flask/lib/python3.5/site-packages/sqlalchemy/sql/elements.py", line 263, in _execute_on_connection
    return connection._execute_clauseelement(self, multiparams, params)
  File "/home/minas/microblog/flask/lib/python3.5/site-packages/sqlalchemy/engine/base.py", line 1053, in _execute_clauseelement
    compiled_sql, distilled_params
  File "/home/minas/microblog/flask/lib/python3.5/site-packages/sqlalchemy/engine/base.py", line 1189, in _execute_context
    context)
  File "/home/minas/microblog/flask/lib/python3.5/site-packages/sqlalchemy/engine/base.py", line 1402, in _handle_dbapi_exception
    exc_info
  File "/home/minas/microblog/flask/lib/python3.5/site-packages/sqlalchemy/util/compat.py", line 203, in raise_from_cause
    reraise(type(exception), exception, tb=exc_tb, cause=cause)
  File "/home/minas/microblog/flask/lib/python3.5/site-packages/sqlalchemy/util/compat.py", line 186, in reraise
    raise value.with_traceback(tb)
  File "/home/minas/microblog/flask/lib/python3.5/site-packages/sqlalchemy/engine/base.py", line 1182, in _execute_context
    context)
  File "/home/minas/microblog/flask/lib/python3.5/site-packages/sqlalchemy/engine/default.py", line 470, in do_execute
    cursor.execute(statement, parameters)
sqlalchemy.exc.IntegrityError: (sqlite3.IntegrityError) UNIQUE constraint failed: user.nickname [SQL: 'INSERT INTO user (nickname, email, about_me, last_seen) VALUES (?, ?, ?, ?)'] [parameters: ('Minas', 'migr94migr@yahoo.com', None, None)]
2017-05-01 01:49:35,746 INFO: microblog startup [in /home/minas/microblog/app/__init__.py:24]
2017-05-01 12:45:52,871 INFO: microblog startup [in /home/minas/microblog/app/__init__.py:24]
2017-05-01 17:23:08,382 INFO: microblog startup [in /home/minas/microblog/app/__init__.py:24]
2017-05-01 17:23:52,492 INFO: microblog startup [in /home/minas/microblog/app/__init__.py:24]
2017-05-01 17:24:05,574 INFO: microblog startup [in /home/minas/microblog/app/__init__.py:24]
2017-05-01 17:33:21,657 INFO: microblog startup [in /home/minas/microblog/app/__init__.py:24]
2017-05-01 17:36:23,816 INFO: microblog startup [in /home/minas/microblog/app/__init__.py:24]
2017-05-01 17:41:51,926 INFO: microblog startup [in /home/minas/microblog/app/__init__.py:24]
2017-05-01 17:43:29,584 INFO: microblog startup [in /home/minas/microblog/app/__init__.py:24]
2017-05-01 17:47:38,588 INFO: microblog startup [in /home/minas/microblog/app/__init__.py:24]
2017-05-01 17:48:59,562 INFO: microblog startup [in /home/minas/microblog/app/__init__.py:24]
2017-05-01 17:50:12,874 INFO: microblog startup [in /home/minas/microblog/app/__init__.py:24]
2017-05-01 17:50:46,382 INFO: microblog startup [in /home/minas/microblog/app/__init__.py:24]
2017-05-01 17:52:41,894 INFO: microblog startup [in /home/minas/microblog/app/__init__.py:24]
2017-05-01 17:52:55,593 ERROR: Exception on /login [GET] [in /home/minas/microblog/flask/lib/python3.5/site-packages/flask/app.py:1560]
Traceback (most recent call last):
  File "/home/minas/microblog/flask/lib/python3.5/site-packages/sqlalchemy/engine/base.py", line 1182, in _execute_context
    context)
  File "/home/minas/microblog/flask/lib/python3.5/site-packages/sqlalchemy/engine/default.py", line 470, in do_execute
    cursor.execute(statement, parameters)
sqlite3.IntegrityError: UNIQUE constraint failed: user.nickname

The above exception was the direct cause of the following exception:

Traceback (most recent call last):
  File "/home/minas/microblog/flask/lib/python3.5/site-packages/flask/app.py", line 1982, in wsgi_app
    response = self.full_dispatch_request()
  File "/home/minas/microblog/flask/lib/python3.5/site-packages/flask/app.py", line 1614, in full_dispatch_request
    rv = self.handle_user_exception(e)
  File "/home/minas/microblog/flask/lib/python3.5/site-packages/flask/app.py", line 1517, in handle_user_exception
    reraise(exc_type, exc_value, tb)
  File "/home/minas/microblog/flask/lib/python3.5/site-packages/flask/_compat.py", line 33, in reraise
    raise value
  File "/home/minas/microblog/flask/lib/python3.5/site-packages/flask/app.py", line 1612, in full_dispatch_request
    rv = self.dispatch_request()
  File "/home/minas/microblog/flask/lib/python3.5/site-packages/flask/app.py", line 1598, in dispatch_request
    return self.view_functions[rule.endpoint](**req.view_args)
  File "/home/minas/microblog/flask/lib/python3.5/site-packages/flask_openid.py", line 507, in decorated
    openid_response, self.extension_responses))
  File "/home/minas/microblog/app/views.py", line 67, in after_login
    db.session.commit()
  File "/home/minas/microblog/flask/lib/python3.5/site-packages/sqlalchemy/orm/scoping.py", line 157, in do
    return getattr(self.registry(), name)(*args, **kwargs)
  File "/home/minas/microblog/flask/lib/python3.5/site-packages/sqlalchemy/orm/session.py", line 874, in commit
    self.transaction.commit()
  File "/home/minas/microblog/flask/lib/python3.5/site-packages/sqlalchemy/orm/session.py", line 461, in commit
    self._prepare_impl()
  File "/home/minas/microblog/flask/lib/python3.5/site-packages/sqlalchemy/orm/session.py", line 441, in _prepare_impl
    self.session.flush()
  File "/home/minas/microblog/flask/lib/python3.5/site-packages/sqlalchemy/orm/session.py", line 2139, in flush
    self._flush(objects)
  File "/home/minas/microblog/flask/lib/python3.5/site-packages/sqlalchemy/orm/session.py", line 2259, in _flush
    transaction.rollback(_capture_exception=True)
  File "/home/minas/microblog/flask/lib/python3.5/site-packages/sqlalchemy/util/langhelpers.py", line 66, in __exit__
    compat.reraise(exc_type, exc_value, exc_tb)
  File "/home/minas/microblog/flask/lib/python3.5/site-packages/sqlalchemy/util/compat.py", line 187, in reraise
    raise value
  File "/home/minas/microblog/flask/lib/python3.5/site-packages/sqlalchemy/orm/session.py", line 2223, in _flush
    flush_context.execute()
  File "/home/minas/microblog/flask/lib/python3.5/site-packages/sqlalchemy/orm/unitofwork.py", line 389, in execute
    rec.execute(self)
  File "/home/minas/microblog/flask/lib/python3.5/site-packages/sqlalchemy/orm/unitofwork.py", line 548, in execute
    uow
  File "/home/minas/microblog/flask/lib/python3.5/site-packages/sqlalchemy/orm/persistence.py", line 181, in save_obj
    mapper, table, insert)
  File "/home/minas/microblog/flask/lib/python3.5/site-packages/sqlalchemy/orm/persistence.py", line 835, in _emit_insert_statements
    execute(statement, params)
  File "/home/minas/microblog/flask/lib/python3.5/site-packages/sqlalchemy/engine/base.py", line 945, in execute
    return meth(self, multiparams, params)
  File "/home/minas/microblog/flask/lib/python3.5/site-packages/sqlalchemy/sql/elements.py", line 263, in _execute_on_connection
    return connection._execute_clauseelement(self, multiparams, params)
  File "/home/minas/microblog/flask/lib/python3.5/site-packages/sqlalchemy/engine/base.py", line 1053, in _execute_clauseelement
    compiled_sql, distilled_params
  File "/home/minas/microblog/flask/lib/python3.5/site-packages/sqlalchemy/engine/base.py", line 1189, in _execute_context
    context)
  File "/home/minas/microblog/flask/lib/python3.5/site-packages/sqlalchemy/engine/base.py", line 1402, in _handle_dbapi_exception
    exc_info
  File "/home/minas/microblog/flask/lib/python3.5/site-packages/sqlalchemy/util/compat.py", line 203, in raise_from_cause
    reraise(type(exception), exception, tb=exc_tb, cause=cause)
  File "/home/minas/microblog/flask/lib/python3.5/site-packages/sqlalchemy/util/compat.py", line 186, in reraise
    raise value.with_traceback(tb)
  File "/home/minas/microblog/flask/lib/python3.5/site-packages/sqlalchemy/engine/base.py", line 1182, in _execute_context
    context)
  File "/home/minas/microblog/flask/lib/python3.5/site-packages/sqlalchemy/engine/default.py", line 470, in do_execute
    cursor.execute(statement, parameters)
sqlalchemy.exc.IntegrityError: (sqlite3.IntegrityError) UNIQUE constraint failed: user.nickname [SQL: 'INSERT INTO user (nickname, email, about_me, last_seen) VALUES (?, ?, ?, ?)'] [parameters: ('Minas', 'migr1994migr@yahoo.com', None, None)]
2017-05-01 17:55:43,986 ERROR: Exception on /login [GET] [in /home/minas/microblog/flask/lib/python3.5/site-packages/flask/app.py:1560]
Traceback (most recent call last):
  File "/home/minas/microblog/flask/lib/python3.5/site-packages/sqlalchemy/engine/base.py", line 1182, in _execute_context
    context)
  File "/home/minas/microblog/flask/lib/python3.5/site-packages/sqlalchemy/engine/default.py", line 470, in do_execute
    cursor.execute(statement, parameters)
sqlite3.IntegrityError: UNIQUE constraint failed: user.nickname

The above exception was the direct cause of the following exception:

Traceback (most recent call last):
  File "/home/minas/microblog/flask/lib/python3.5/site-packages/flask/app.py", line 1982, in wsgi_app
    response = self.full_dispatch_request()
  File "/home/minas/microblog/flask/lib/python3.5/site-packages/flask/app.py", line 1614, in full_dispatch_request
    rv = self.handle_user_exception(e)
  File "/home/minas/microblog/flask/lib/python3.5/site-packages/flask/app.py", line 1517, in handle_user_exception
    reraise(exc_type, exc_value, tb)
  File "/home/minas/microblog/flask/lib/python3.5/site-packages/flask/_compat.py", line 33, in reraise
    raise value
  File "/home/minas/microblog/flask/lib/python3.5/site-packages/flask/app.py", line 1612, in full_dispatch_request
    rv = self.dispatch_request()
  File "/home/minas/microblog/flask/lib/python3.5/site-packages/flask/app.py", line 1598, in dispatch_request
    return self.view_functions[rule.endpoint](**req.view_args)
  File "/home/minas/microblog/flask/lib/python3.5/site-packages/flask_openid.py", line 507, in decorated
    openid_response, self.extension_responses))
  File "/home/minas/microblog/app/views.py", line 67, in after_login
    db.session.commit()
  File "/home/minas/microblog/flask/lib/python3.5/site-packages/sqlalchemy/orm/scoping.py", line 157, in do
    return getattr(self.registry(), name)(*args, **kwargs)
  File "/home/minas/microblog/flask/lib/python3.5/site-packages/sqlalchemy/orm/session.py", line 874, in commit
    self.transaction.commit()
  File "/home/minas/microblog/flask/lib/python3.5/site-packages/sqlalchemy/orm/session.py", line 461, in commit
    self._prepare_impl()
  File "/home/minas/microblog/flask/lib/python3.5/site-packages/sqlalchemy/orm/session.py", line 441, in _prepare_impl
    self.session.flush()
  File "/home/minas/microblog/flask/lib/python3.5/site-packages/sqlalchemy/orm/session.py", line 2139, in flush
    self._flush(objects)
  File "/home/minas/microblog/flask/lib/python3.5/site-packages/sqlalchemy/orm/session.py", line 2259, in _flush
    transaction.rollback(_capture_exception=True)
  File "/home/minas/microblog/flask/lib/python3.5/site-packages/sqlalchemy/util/langhelpers.py", line 66, in __exit__
    compat.reraise(exc_type, exc_value, exc_tb)
  File "/home/minas/microblog/flask/lib/python3.5/site-packages/sqlalchemy/util/compat.py", line 187, in reraise
    raise value
  File "/home/minas/microblog/flask/lib/python3.5/site-packages/sqlalchemy/orm/session.py", line 2223, in _flush
    flush_context.execute()
  File "/home/minas/microblog/flask/lib/python3.5/site-packages/sqlalchemy/orm/unitofwork.py", line 389, in execute
    rec.execute(self)
  File "/home/minas/microblog/flask/lib/python3.5/site-packages/sqlalchemy/orm/unitofwork.py", line 548, in execute
    uow
  File "/home/minas/microblog/flask/lib/python3.5/site-packages/sqlalchemy/orm/persistence.py", line 181, in save_obj
    mapper, table, insert)
  File "/home/minas/microblog/flask/lib/python3.5/site-packages/sqlalchemy/orm/persistence.py", line 835, in _emit_insert_statements
    execute(statement, params)
  File "/home/minas/microblog/flask/lib/python3.5/site-packages/sqlalchemy/engine/base.py", line 945, in execute
    return meth(self, multiparams, params)
  File "/home/minas/microblog/flask/lib/python3.5/site-packages/sqlalchemy/sql/elements.py", line 263, in _execute_on_connection
    return connection._execute_clauseelement(self, multiparams, params)
  File "/home/minas/microblog/flask/lib/python3.5/site-packages/sqlalchemy/engine/base.py", line 1053, in _execute_clauseelement
    compiled_sql, distilled_params
  File "/home/minas/microblog/flask/lib/python3.5/site-packages/sqlalchemy/engine/base.py", line 1189, in _execute_context
    context)
  File "/home/minas/microblog/flask/lib/python3.5/site-packages/sqlalchemy/engine/base.py", line 1402, in _handle_dbapi_exception
    exc_info
  File "/home/minas/microblog/flask/lib/python3.5/site-packages/sqlalchemy/util/compat.py", line 203, in raise_from_cause
    reraise(type(exception), exception, tb=exc_tb, cause=cause)
  File "/home/minas/microblog/flask/lib/python3.5/site-packages/sqlalchemy/util/compat.py", line 186, in reraise
    raise value.with_traceback(tb)
  File "/home/minas/microblog/flask/lib/python3.5/site-packages/sqlalchemy/engine/base.py", line 1182, in _execute_context
    context)
  File "/home/minas/microblog/flask/lib/python3.5/site-packages/sqlalchemy/engine/default.py", line 470, in do_execute
    cursor.execute(statement, parameters)
sqlalchemy.exc.IntegrityError: (sqlite3.IntegrityError) UNIQUE constraint failed: user.nickname [SQL: 'INSERT INTO user (nickname, email, about_me, last_seen) VALUES (?, ?, ?, ?)'] [parameters: ('Minas', 'migr1994migr@yahoo.com', None, None)]
2017-05-01 17:56:08,391 INFO: microblog startup [in /home/minas/microblog/app/__init__.py:24]
2017-05-01 17:58:34,981 INFO: microblog startup [in /home/minas/microblog/app/__init__.py:24]
2017-05-01 18:47:56,862 INFO: microblog startup [in /home/minas/microblog/app/__init__.py:24]
2017-05-01 18:48:12,175 INFO: microblog startup [in /home/minas/microblog/app/__init__.py:24]
2017-05-01 18:52:39,489 INFO: microblog startup [in /home/minas/microblog/app/__init__.py:24]
2017-05-01 18:55:14,081 INFO: microblog startup [in /home/minas/microblog/app/__init__.py:24]
2017-05-01 18:58:36,680 ERROR: Exception on /user/Anna [GET] [in /home/minas/microblog/flask/lib/python3.5/site-packages/flask/app.py:1560]
Traceback (most recent call last):
  File "/home/minas/microblog/flask/lib/python3.5/site-packages/flask/app.py", line 1982, in wsgi_app
    response = self.full_dispatch_request()
  File "/home/minas/microblog/flask/lib/python3.5/site-packages/flask/app.py", line 1614, in full_dispatch_request
    rv = self.handle_user_exception(e)
  File "/home/minas/microblog/flask/lib/python3.5/site-packages/flask/app.py", line 1517, in handle_user_exception
    reraise(exc_type, exc_value, tb)
  File "/home/minas/microblog/flask/lib/python3.5/site-packages/flask/_compat.py", line 33, in reraise
    raise value
  File "/home/minas/microblog/flask/lib/python3.5/site-packages/flask/app.py", line 1612, in full_dispatch_request
    rv = self.dispatch_request()
  File "/home/minas/microblog/flask/lib/python3.5/site-packages/flask/app.py", line 1598, in dispatch_request
    return self.view_functions[rule.endpoint](**req.view_args)
  File "/home/minas/microblog/flask/lib/python3.5/site-packages/flask_login/utils.py", line 228, in decorated_view
    return func(*args, **kwargs)
  File "/home/minas/microblog/app/views.py", line 98, in user
    posts=posts)
  File "/home/minas/microblog/flask/lib/python3.5/site-packages/flask/templating.py", line 134, in render_template
    context, ctx.app)
  File "/home/minas/microblog/flask/lib/python3.5/site-packages/flask/templating.py", line 116, in _render
    rv = template.render(context)
  File "/home/minas/microblog/flask/lib/python3.5/site-packages/jinja2/environment.py", line 1008, in render
    return self.environment.handle_exception(exc_info, True)
  File "/home/minas/microblog/flask/lib/python3.5/site-packages/jinja2/environment.py", line 780, in handle_exception
    reraise(exc_type, exc_value, tb)
  File "/home/minas/microblog/flask/lib/python3.5/site-packages/jinja2/_compat.py", line 37, in reraise
    raise value.with_traceback(tb)
  File "/home/minas/microblog/app/templates/user.html", line 2, in top-level template code
    {% extends "base.html" %}
  File "/home/minas/microblog/app/templates/base.html", line 27, in top-level template code
    {% block content %}{% endblock %}
  File "/home/minas/microblog/app/templates/user.html", line 16, in block "content"
    <a href="{{ url_for('follow', nickname=user.nickname) }}">Follow</a>
  File "/home/minas/microblog/flask/lib/python3.5/site-packages/flask/helpers.py", line 333, in url_for
    return appctx.app.handle_url_build_error(error, endpoint, values)
  File "/home/minas/microblog/flask/lib/python3.5/site-packages/flask/app.py", line 1805, in handle_url_build_error
    reraise(exc_type, exc_value, tb)
  File "/home/minas/microblog/flask/lib/python3.5/site-packages/flask/_compat.py", line 33, in reraise
    raise value
  File "/home/minas/microblog/flask/lib/python3.5/site-packages/flask/helpers.py", line 323, in url_for
    force_external=external)
  File "/home/minas/microblog/flask/lib/python3.5/site-packages/werkzeug/routing.py", line 1768, in build
    raise BuildError(endpoint, values, method, self)
werkzeug.routing.BuildError: Could not build url for endpoint 'follow' with values ['nickname']. Did you mean 'login' instead?
2017-05-01 18:58:49,649 ERROR: Exception on /user/Anna [GET] [in /home/minas/microblog/flask/lib/python3.5/site-packages/flask/app.py:1560]
Traceback (most recent call last):
  File "/home/minas/microblog/flask/lib/python3.5/site-packages/flask/app.py", line 1982, in wsgi_app
    response = self.full_dispatch_request()
  File "/home/minas/microblog/flask/lib/python3.5/site-packages/flask/app.py", line 1614, in full_dispatch_request
    rv = self.handle_user_exception(e)
  File "/home/minas/microblog/flask/lib/python3.5/site-packages/flask/app.py", line 1517, in handle_user_exception
    reraise(exc_type, exc_value, tb)
  File "/home/minas/microblog/flask/lib/python3.5/site-packages/flask/_compat.py", line 33, in reraise
    raise value
  File "/home/minas/microblog/flask/lib/python3.5/site-packages/flask/app.py", line 1612, in full_dispatch_request
    rv = self.dispatch_request()
  File "/home/minas/microblog/flask/lib/python3.5/site-packages/flask/app.py", line 1598, in dispatch_request
    return self.view_functions[rule.endpoint](**req.view_args)
  File "/home/minas/microblog/flask/lib/python3.5/site-packages/flask_login/utils.py", line 228, in decorated_view
    return func(*args, **kwargs)
  File "/home/minas/microblog/app/views.py", line 98, in user
    posts=posts)
  File "/home/minas/microblog/flask/lib/python3.5/site-packages/flask/templating.py", line 134, in render_template
    context, ctx.app)
  File "/home/minas/microblog/flask/lib/python3.5/site-packages/flask/templating.py", line 116, in _render
    rv = template.render(context)
  File "/home/minas/microblog/flask/lib/python3.5/site-packages/jinja2/environment.py", line 1008, in render
    return self.environment.handle_exception(exc_info, True)
  File "/home/minas/microblog/flask/lib/python3.5/site-packages/jinja2/environment.py", line 780, in handle_exception
    reraise(exc_type, exc_value, tb)
  File "/home/minas/microblog/flask/lib/python3.5/site-packages/jinja2/_compat.py", line 37, in reraise
    raise value.with_traceback(tb)
  File "/home/minas/microblog/app/templates/user.html", line 2, in top-level template code
    {% extends "base.html" %}
  File "/home/minas/microblog/app/templates/base.html", line 27, in top-level template code
    {% block content %}{% endblock %}
  File "/home/minas/microblog/app/templates/user.html", line 16, in block "content"
    <a href="{{ url_for('follow', nickname=user.nickname) }}">Follow</a>
  File "/home/minas/microblog/flask/lib/python3.5/site-packages/flask/helpers.py", line 333, in url_for
    return appctx.app.handle_url_build_error(error, endpoint, values)
  File "/home/minas/microblog/flask/lib/python3.5/site-packages/flask/app.py", line 1805, in handle_url_build_error
    reraise(exc_type, exc_value, tb)
  File "/home/minas/microblog/flask/lib/python3.5/site-packages/flask/_compat.py", line 33, in reraise
    raise value
  File "/home/minas/microblog/flask/lib/python3.5/site-packages/flask/helpers.py", line 323, in url_for
    force_external=external)
  File "/home/minas/microblog/flask/lib/python3.5/site-packages/werkzeug/routing.py", line 1768, in build
    raise BuildError(endpoint, values, method, self)
werkzeug.routing.BuildError: Could not build url for endpoint 'follow' with values ['nickname']. Did you mean 'login' instead?
2017-05-01 18:59:13,282 ERROR: Exception on /user/Anna [GET] [in /home/minas/microblog/flask/lib/python3.5/site-packages/flask/app.py:1560]
Traceback (most recent call last):
  File "/home/minas/microblog/flask/lib/python3.5/site-packages/flask/app.py", line 1982, in wsgi_app
    response = self.full_dispatch_request()
  File "/home/minas/microblog/flask/lib/python3.5/site-packages/flask/app.py", line 1614, in full_dispatch_request
    rv = self.handle_user_exception(e)
  File "/home/minas/microblog/flask/lib/python3.5/site-packages/flask/app.py", line 1517, in handle_user_exception
    reraise(exc_type, exc_value, tb)
  File "/home/minas/microblog/flask/lib/python3.5/site-packages/flask/_compat.py", line 33, in reraise
    raise value
  File "/home/minas/microblog/flask/lib/python3.5/site-packages/flask/app.py", line 1612, in full_dispatch_request
    rv = self.dispatch_request()
  File "/home/minas/microblog/flask/lib/python3.5/site-packages/flask/app.py", line 1598, in dispatch_request
    return self.view_functions[rule.endpoint](**req.view_args)
  File "/home/minas/microblog/flask/lib/python3.5/site-packages/flask_login/utils.py", line 228, in decorated_view
    return func(*args, **kwargs)
  File "/home/minas/microblog/app/views.py", line 98, in user
    posts=posts)
  File "/home/minas/microblog/flask/lib/python3.5/site-packages/flask/templating.py", line 134, in render_template
    context, ctx.app)
  File "/home/minas/microblog/flask/lib/python3.5/site-packages/flask/templating.py", line 116, in _render
    rv = template.render(context)
  File "/home/minas/microblog/flask/lib/python3.5/site-packages/jinja2/environment.py", line 1008, in render
    return self.environment.handle_exception(exc_info, True)
  File "/home/minas/microblog/flask/lib/python3.5/site-packages/jinja2/environment.py", line 780, in handle_exception
    reraise(exc_type, exc_value, tb)
  File "/home/minas/microblog/flask/lib/python3.5/site-packages/jinja2/_compat.py", line 37, in reraise
    raise value.with_traceback(tb)
  File "/home/minas/microblog/app/templates/user.html", line 2, in top-level template code
    {% extends "base.html" %}
  File "/home/minas/microblog/app/templates/base.html", line 27, in top-level template code
    {% block content %}{% endblock %}
  File "/home/minas/microblog/app/templates/user.html", line 16, in block "content"
    <a href="{{ url_for('follow', nickname=user.nickname) }}">Follow</a>
  File "/home/minas/microblog/flask/lib/python3.5/site-packages/flask/helpers.py", line 333, in url_for
    return appctx.app.handle_url_build_error(error, endpoint, values)
  File "/home/minas/microblog/flask/lib/python3.5/site-packages/flask/app.py", line 1805, in handle_url_build_error
    reraise(exc_type, exc_value, tb)
  File "/home/minas/microblog/flask/lib/python3.5/site-packages/flask/_compat.py", line 33, in reraise
    raise value
  File "/home/minas/microblog/flask/lib/python3.5/site-packages/flask/helpers.py", line 323, in url_for
    force_external=external)
  File "/home/minas/microblog/flask/lib/python3.5/site-packages/werkzeug/routing.py", line 1768, in build
    raise BuildError(endpoint, values, method, self)
werkzeug.routing.BuildError: Could not build url for endpoint 'follow' with values ['nickname']. Did you mean 'login' instead?
2017-05-01 18:59:31,097 ERROR: Exception on /user/Tigran [GET] [in /home/minas/microblog/flask/lib/python3.5/site-packages/flask/app.py:1560]
Traceback (most recent call last):
  File "/home/minas/microblog/flask/lib/python3.5/site-packages/flask/app.py", line 1982, in wsgi_app
    response = self.full_dispatch_request()
  File "/home/minas/microblog/flask/lib/python3.5/site-packages/flask/app.py", line 1614, in full_dispatch_request
    rv = self.handle_user_exception(e)
  File "/home/minas/microblog/flask/lib/python3.5/site-packages/flask/app.py", line 1517, in handle_user_exception
    reraise(exc_type, exc_value, tb)
  File "/home/minas/microblog/flask/lib/python3.5/site-packages/flask/_compat.py", line 33, in reraise
    raise value
  File "/home/minas/microblog/flask/lib/python3.5/site-packages/flask/app.py", line 1612, in full_dispatch_request
    rv = self.dispatch_request()
  File "/home/minas/microblog/flask/lib/python3.5/site-packages/flask/app.py", line 1598, in dispatch_request
    return self.view_functions[rule.endpoint](**req.view_args)
  File "/home/minas/microblog/flask/lib/python3.5/site-packages/flask_login/utils.py", line 228, in decorated_view
    return func(*args, **kwargs)
  File "/home/minas/microblog/app/views.py", line 98, in user
    posts=posts)
  File "/home/minas/microblog/flask/lib/python3.5/site-packages/flask/templating.py", line 134, in render_template
    context, ctx.app)
  File "/home/minas/microblog/flask/lib/python3.5/site-packages/flask/templating.py", line 116, in _render
    rv = template.render(context)
  File "/home/minas/microblog/flask/lib/python3.5/site-packages/jinja2/environment.py", line 1008, in render
    return self.environment.handle_exception(exc_info, True)
  File "/home/minas/microblog/flask/lib/python3.5/site-packages/jinja2/environment.py", line 780, in handle_exception
    reraise(exc_type, exc_value, tb)
  File "/home/minas/microblog/flask/lib/python3.5/site-packages/jinja2/_compat.py", line 37, in reraise
    raise value.with_traceback(tb)
  File "/home/minas/microblog/app/templates/user.html", line 2, in top-level template code
    {% extends "base.html" %}
  File "/home/minas/microblog/app/templates/base.html", line 27, in top-level template code
    {% block content %}{% endblock %}
  File "/home/minas/microblog/app/templates/user.html", line 16, in block "content"
    <a href="{{ url_for('follow', nickname=user.nickname) }}">Follow</a>
  File "/home/minas/microblog/flask/lib/python3.5/site-packages/flask/helpers.py", line 333, in url_for
    return appctx.app.handle_url_build_error(error, endpoint, values)
  File "/home/minas/microblog/flask/lib/python3.5/site-packages/flask/app.py", line 1805, in handle_url_build_error
    reraise(exc_type, exc_value, tb)
  File "/home/minas/microblog/flask/lib/python3.5/site-packages/flask/_compat.py", line 33, in reraise
    raise value
  File "/home/minas/microblog/flask/lib/python3.5/site-packages/flask/helpers.py", line 323, in url_for
    force_external=external)
  File "/home/minas/microblog/flask/lib/python3.5/site-packages/werkzeug/routing.py", line 1768, in build
    raise BuildError(endpoint, values, method, self)
werkzeug.routing.BuildError: Could not build url for endpoint 'follow' with values ['nickname']. Did you mean 'login' instead?
2017-05-01 19:00:12,165 ERROR: Exception on /user/Anna [GET] [in /home/minas/microblog/flask/lib/python3.5/site-packages/flask/app.py:1560]
Traceback (most recent call last):
  File "/home/minas/microblog/flask/lib/python3.5/site-packages/flask/app.py", line 1982, in wsgi_app
    response = self.full_dispatch_request()
  File "/home/minas/microblog/flask/lib/python3.5/site-packages/flask/app.py", line 1614, in full_dispatch_request
    rv = self.handle_user_exception(e)
  File "/home/minas/microblog/flask/lib/python3.5/site-packages/flask/app.py", line 1517, in handle_user_exception
    reraise(exc_type, exc_value, tb)
  File "/home/minas/microblog/flask/lib/python3.5/site-packages/flask/_compat.py", line 33, in reraise
    raise value
  File "/home/minas/microblog/flask/lib/python3.5/site-packages/flask/app.py", line 1612, in full_dispatch_request
    rv = self.dispatch_request()
  File "/home/minas/microblog/flask/lib/python3.5/site-packages/flask/app.py", line 1598, in dispatch_request
    return self.view_functions[rule.endpoint](**req.view_args)
  File "/home/minas/microblog/flask/lib/python3.5/site-packages/flask_login/utils.py", line 228, in decorated_view
    return func(*args, **kwargs)
  File "/home/minas/microblog/app/views.py", line 98, in user
    posts=posts)
  File "/home/minas/microblog/flask/lib/python3.5/site-packages/flask/templating.py", line 134, in render_template
    context, ctx.app)
  File "/home/minas/microblog/flask/lib/python3.5/site-packages/flask/templating.py", line 116, in _render
    rv = template.render(context)
  File "/home/minas/microblog/flask/lib/python3.5/site-packages/jinja2/environment.py", line 1008, in render
    return self.environment.handle_exception(exc_info, True)
  File "/home/minas/microblog/flask/lib/python3.5/site-packages/jinja2/environment.py", line 780, in handle_exception
    reraise(exc_type, exc_value, tb)
  File "/home/minas/microblog/flask/lib/python3.5/site-packages/jinja2/_compat.py", line 37, in reraise
    raise value.with_traceback(tb)
  File "/home/minas/microblog/app/templates/user.html", line 2, in top-level template code
    {% extends "base.html" %}
  File "/home/minas/microblog/app/templates/base.html", line 27, in top-level template code
    {% block content %}{% endblock %}
  File "/home/minas/microblog/app/templates/user.html", line 16, in block "content"
    <a href="{{ url_for('follow', nickname=user.nickname) }}">Follow</a>
  File "/home/minas/microblog/flask/lib/python3.5/site-packages/flask/helpers.py", line 333, in url_for
    return appctx.app.handle_url_build_error(error, endpoint, values)
  File "/home/minas/microblog/flask/lib/python3.5/site-packages/flask/app.py", line 1805, in handle_url_build_error
    reraise(exc_type, exc_value, tb)
  File "/home/minas/microblog/flask/lib/python3.5/site-packages/flask/_compat.py", line 33, in reraise
    raise value
  File "/home/minas/microblog/flask/lib/python3.5/site-packages/flask/helpers.py", line 323, in url_for
    force_external=external)
  File "/home/minas/microblog/flask/lib/python3.5/site-packages/werkzeug/routing.py", line 1768, in build
    raise BuildError(endpoint, values, method, self)
werkzeug.routing.BuildError: Could not build url for endpoint 'follow' with values ['nickname']. Did you mean 'login' instead?
2017-05-01 19:00:57,572 ERROR: Exception on /user/Anna [GET] [in /home/minas/microblog/flask/lib/python3.5/site-packages/flask/app.py:1560]
Traceback (most recent call last):
  File "/home/minas/microblog/flask/lib/python3.5/site-packages/flask/app.py", line 1982, in wsgi_app
    response = self.full_dispatch_request()
  File "/home/minas/microblog/flask/lib/python3.5/site-packages/flask/app.py", line 1614, in full_dispatch_request
    rv = self.handle_user_exception(e)
  File "/home/minas/microblog/flask/lib/python3.5/site-packages/flask/app.py", line 1517, in handle_user_exception
    reraise(exc_type, exc_value, tb)
  File "/home/minas/microblog/flask/lib/python3.5/site-packages/flask/_compat.py", line 33, in reraise
    raise value
  File "/home/minas/microblog/flask/lib/python3.5/site-packages/flask/app.py", line 1612, in full_dispatch_request
    rv = self.dispatch_request()
  File "/home/minas/microblog/flask/lib/python3.5/site-packages/flask/app.py", line 1598, in dispatch_request
    return self.view_functions[rule.endpoint](**req.view_args)
  File "/home/minas/microblog/flask/lib/python3.5/site-packages/flask_login/utils.py", line 228, in decorated_view
    return func(*args, **kwargs)
  File "/home/minas/microblog/app/views.py", line 98, in user
    posts=posts)
  File "/home/minas/microblog/flask/lib/python3.5/site-packages/flask/templating.py", line 134, in render_template
    context, ctx.app)
  File "/home/minas/microblog/flask/lib/python3.5/site-packages/flask/templating.py", line 116, in _render
    rv = template.render(context)
  File "/home/minas/microblog/flask/lib/python3.5/site-packages/jinja2/environment.py", line 1008, in render
    return self.environment.handle_exception(exc_info, True)
  File "/home/minas/microblog/flask/lib/python3.5/site-packages/jinja2/environment.py", line 780, in handle_exception
    reraise(exc_type, exc_value, tb)
  File "/home/minas/microblog/flask/lib/python3.5/site-packages/jinja2/_compat.py", line 37, in reraise
    raise value.with_traceback(tb)
  File "/home/minas/microblog/app/templates/user.html", line 2, in top-level template code
    {% extends "base.html" %}
  File "/home/minas/microblog/app/templates/base.html", line 27, in top-level template code
    {% block content %}{% endblock %}
  File "/home/minas/microblog/app/templates/user.html", line 16, in block "content"
    <a href="{{ url_for('follow', nickname=user.nickname) }}">Follow</a>
  File "/home/minas/microblog/flask/lib/python3.5/site-packages/flask/helpers.py", line 333, in url_for
    return appctx.app.handle_url_build_error(error, endpoint, values)
  File "/home/minas/microblog/flask/lib/python3.5/site-packages/flask/app.py", line 1805, in handle_url_build_error
    reraise(exc_type, exc_value, tb)
  File "/home/minas/microblog/flask/lib/python3.5/site-packages/flask/_compat.py", line 33, in reraise
    raise value
  File "/home/minas/microblog/flask/lib/python3.5/site-packages/flask/helpers.py", line 323, in url_for
    force_external=external)
  File "/home/minas/microblog/flask/lib/python3.5/site-packages/werkzeug/routing.py", line 1768, in build
    raise BuildError(endpoint, values, method, self)
werkzeug.routing.BuildError: Could not build url for endpoint 'follow' with values ['nickname']. Did you mean 'login' instead?
2017-05-01 19:01:23,874 INFO: microblog startup [in /home/minas/microblog/app/__init__.py:24]
2017-05-01 19:03:03,062 INFO: microblog startup [in /home/minas/microblog/app/__init__.py:24]
2017-05-01 19:37:41,999 INFO: microblog startup [in /home/minas/microblog/app/__init__.py:24]
2017-05-01 19:38:32,545 INFO: microblog startup [in /home/minas/microblog/app/__init__.py:24]
2017-05-01 19:40:32,431 INFO: microblog startup [in /home/minas/microblog/app/__init__.py:24]
2017-05-01 19:41:14,198 INFO: microblog startup [in /home/minas/microblog/app/__init__.py:24]
2017-05-01 19:42:51,325 INFO: microblog startup [in /home/minas/microblog/app/__init__.py:24]
2017-05-01 19:44:03,864 INFO: microblog startup [in /home/minas/microblog/app/__init__.py:24]
2017-05-01 19:44:34,085 INFO: microblog startup [in /home/minas/microblog/app/__init__.py:24]
2017-05-01 20:08:36,139 INFO: microblog startup [in /home/minas/microblog/app/__init__.py:24]
2017-05-01 20:08:42,472 INFO: microblog startup [in /home/minas/microblog/app/__init__.py:24]
2017-05-01 20:13:35,103 INFO: microblog startup [in /home/minas/microblog/app/__init__.py:24]
2017-05-01 20:15:06,320 INFO: microblog startup [in /home/minas/microblog/app/__init__.py:24]
2017-05-01 20:15:47,033 INFO: microblog startup [in /home/minas/microblog/app/__init__.py:24]
2017-05-01 20:18:37,260 INFO: microblog startup [in /home/minas/microblog/app/__init__.py:24]
2017-05-01 20:19:21,350 INFO: microblog startup [in /home/minas/microblog/app/__init__.py:24]
2017-05-01 20:21:09,681 INFO: microblog startup [in /home/minas/microblog/app/__init__.py:24]
2017-05-01 20:30:37,976 INFO: microblog startup [in /home/minas/microblog/app/__init__.py:24]
2017-05-01 20:30:41,326 INFO: microblog startup [in /home/minas/microblog/app/__init__.py:24]
2017-05-01 20:32:10,087 INFO: microblog startup [in /home/minas/microblog/app/__init__.py:24]
2017-05-01 20:37:00,606 INFO: microblog startup [in /home/minas/microblog/app/__init__.py:24]
2017-05-01 20:52:58,316 INFO: microblog startup [in /home/minas/microblog/app/__init__.py:24]
2017-05-01 20:53:01,650 INFO: microblog startup [in /home/minas/microblog/app/__init__.py:24]
2017-05-01 20:53:05,075 ERROR: Exception on /index [GET] [in /home/minas/microblog/flask/lib/python3.5/site-packages/flask/app.py:1560]
Traceback (most recent call last):
  File "/home/minas/microblog/flask/lib/python3.5/site-packages/flask/app.py", line 1982, in wsgi_app
    response = self.full_dispatch_request()
  File "/home/minas/microblog/flask/lib/python3.5/site-packages/flask/app.py", line 1614, in full_dispatch_request
    rv = self.handle_user_exception(e)
  File "/home/minas/microblog/flask/lib/python3.5/site-packages/flask/app.py", line 1517, in handle_user_exception
    reraise(exc_type, exc_value, tb)
  File "/home/minas/microblog/flask/lib/python3.5/site-packages/flask/_compat.py", line 33, in reraise
    raise value
  File "/home/minas/microblog/flask/lib/python3.5/site-packages/flask/app.py", line 1612, in full_dispatch_request
    rv = self.dispatch_request()
  File "/home/minas/microblog/flask/lib/python3.5/site-packages/flask/app.py", line 1598, in dispatch_request
    return self.view_functions[rule.endpoint](**req.view_args)
  File "/home/minas/microblog/flask/lib/python3.5/site-packages/flask_login/utils.py", line 228, in decorated_view
    return func(*args, **kwargs)
  File "/home/minas/microblog/app/views.py", line 37, in index
    posts=posts)
  File "/home/minas/microblog/flask/lib/python3.5/site-packages/flask/templating.py", line 133, in render_template
    return _render(ctx.app.jinja_env.get_or_select_template(template_name_or_list),
  File "/home/minas/microblog/flask/lib/python3.5/site-packages/jinja2/environment.py", line 869, in get_or_select_template
    return self.get_template(template_name_or_list, parent, globals)
  File "/home/minas/microblog/flask/lib/python3.5/site-packages/jinja2/environment.py", line 830, in get_template
    return self._load_template(name, self.make_globals(globals))
  File "/home/minas/microblog/flask/lib/python3.5/site-packages/jinja2/environment.py", line 804, in _load_template
    template = self.loader.load(self, name, globals)
  File "/home/minas/microblog/flask/lib/python3.5/site-packages/jinja2/loaders.py", line 125, in load
    code = environment.compile(source, name, filename)
  File "/home/minas/microblog/flask/lib/python3.5/site-packages/jinja2/environment.py", line 591, in compile
    self.handle_exception(exc_info, source_hint=source_hint)
  File "/home/minas/microblog/flask/lib/python3.5/site-packages/jinja2/environment.py", line 780, in handle_exception
    reraise(exc_type, exc_value, tb)
  File "/home/minas/microblog/flask/lib/python3.5/site-packages/jinja2/_compat.py", line 37, in reraise
    raise value.with_traceback(tb)
  File "/home/minas/microblog/app/templates/index.html", line 32, in template
    {% endfor %}
  File "/home/minas/microblog/flask/lib/python3.5/site-packages/jinja2/environment.py", line 497, in _parse
    return Parser(self, source, name, encode_filename(filename)).parse()
  File "/home/minas/microblog/flask/lib/python3.5/site-packages/jinja2/parser.py", line 896, in parse
    result = nodes.Template(self.subparse(), lineno=1)
  File "/home/minas/microblog/flask/lib/python3.5/site-packages/jinja2/parser.py", line 878, in subparse
    rv = self.parse_statement()
  File "/home/minas/microblog/flask/lib/python3.5/site-packages/jinja2/parser.py", line 130, in parse_statement
    return getattr(self, 'parse_' + self.stream.current.value)()
  File "/home/minas/microblog/flask/lib/python3.5/site-packages/jinja2/parser.py", line 268, in parse_block
    node.body = self.parse_statements(('name:endblock',), drop_needle=True)
  File "/home/minas/microblog/flask/lib/python3.5/site-packages/jinja2/parser.py", line 165, in parse_statements
    result = self.subparse(end_tokens)
  File "/home/minas/microblog/flask/lib/python3.5/site-packages/jinja2/parser.py", line 878, in subparse
    rv = self.parse_statement()
  File "/home/minas/microblog/flask/lib/python3.5/site-packages/jinja2/parser.py", line 144, in parse_statement
    self.fail_unknown_tag(token.value, token.lineno)
  File "/home/minas/microblog/flask/lib/python3.5/site-packages/jinja2/parser.py", line 97, in fail_unknown_tag
    return self._fail_ut_eof(name, self._end_token_stack, lineno)
  File "/home/minas/microblog/flask/lib/python3.5/site-packages/jinja2/parser.py", line 90, in _fail_ut_eof
    self.fail(' '.join(message), lineno)
  File "/home/minas/microblog/flask/lib/python3.5/site-packages/jinja2/parser.py", line 59, in fail
    raise exc(msg, lineno, self.name, self.filename)
jinja2.exceptions.TemplateSyntaxError: Encountered unknown tag 'endfor'. Jinja was looking for the following tags: 'endblock'. The innermost block that needs to be closed is 'block'.
2017-05-01 20:53:07,749 ERROR: Exception on /index [GET] [in /home/minas/microblog/flask/lib/python3.5/site-packages/flask/app.py:1560]
Traceback (most recent call last):
  File "/home/minas/microblog/flask/lib/python3.5/site-packages/flask/app.py", line 1982, in wsgi_app
    response = self.full_dispatch_request()
  File "/home/minas/microblog/flask/lib/python3.5/site-packages/flask/app.py", line 1614, in full_dispatch_request
    rv = self.handle_user_exception(e)
  File "/home/minas/microblog/flask/lib/python3.5/site-packages/flask/app.py", line 1517, in handle_user_exception
    reraise(exc_type, exc_value, tb)
  File "/home/minas/microblog/flask/lib/python3.5/site-packages/flask/_compat.py", line 33, in reraise
    raise value
  File "/home/minas/microblog/flask/lib/python3.5/site-packages/flask/app.py", line 1612, in full_dispatch_request
    rv = self.dispatch_request()
  File "/home/minas/microblog/flask/lib/python3.5/site-packages/flask/app.py", line 1598, in dispatch_request
    return self.view_functions[rule.endpoint](**req.view_args)
  File "/home/minas/microblog/flask/lib/python3.5/site-packages/flask_login/utils.py", line 228, in decorated_view
    return func(*args, **kwargs)
  File "/home/minas/microblog/app/views.py", line 37, in index
    posts=posts)
  File "/home/minas/microblog/flask/lib/python3.5/site-packages/flask/templating.py", line 133, in render_template
    return _render(ctx.app.jinja_env.get_or_select_template(template_name_or_list),
  File "/home/minas/microblog/flask/lib/python3.5/site-packages/jinja2/environment.py", line 869, in get_or_select_template
    return self.get_template(template_name_or_list, parent, globals)
  File "/home/minas/microblog/flask/lib/python3.5/site-packages/jinja2/environment.py", line 830, in get_template
    return self._load_template(name, self.make_globals(globals))
  File "/home/minas/microblog/flask/lib/python3.5/site-packages/jinja2/environment.py", line 804, in _load_template
    template = self.loader.load(self, name, globals)
  File "/home/minas/microblog/flask/lib/python3.5/site-packages/jinja2/loaders.py", line 125, in load
    code = environment.compile(source, name, filename)
  File "/home/minas/microblog/flask/lib/python3.5/site-packages/jinja2/environment.py", line 591, in compile
    self.handle_exception(exc_info, source_hint=source_hint)
  File "/home/minas/microblog/flask/lib/python3.5/site-packages/jinja2/environment.py", line 780, in handle_exception
    reraise(exc_type, exc_value, tb)
  File "/home/minas/microblog/flask/lib/python3.5/site-packages/jinja2/_compat.py", line 37, in reraise
    raise value.with_traceback(tb)
  File "/home/minas/microblog/app/templates/index.html", line 32, in template
    {% endfor %}
  File "/home/minas/microblog/flask/lib/python3.5/site-packages/jinja2/environment.py", line 497, in _parse
    return Parser(self, source, name, encode_filename(filename)).parse()
  File "/home/minas/microblog/flask/lib/python3.5/site-packages/jinja2/parser.py", line 896, in parse
    result = nodes.Template(self.subparse(), lineno=1)
  File "/home/minas/microblog/flask/lib/python3.5/site-packages/jinja2/parser.py", line 878, in subparse
    rv = self.parse_statement()
  File "/home/minas/microblog/flask/lib/python3.5/site-packages/jinja2/parser.py", line 130, in parse_statement
    return getattr(self, 'parse_' + self.stream.current.value)()
  File "/home/minas/microblog/flask/lib/python3.5/site-packages/jinja2/parser.py", line 268, in parse_block
    node.body = self.parse_statements(('name:endblock',), drop_needle=True)
  File "/home/minas/microblog/flask/lib/python3.5/site-packages/jinja2/parser.py", line 165, in parse_statements
    result = self.subparse(end_tokens)
  File "/home/minas/microblog/flask/lib/python3.5/site-packages/jinja2/parser.py", line 878, in subparse
    rv = self.parse_statement()
  File "/home/minas/microblog/flask/lib/python3.5/site-packages/jinja2/parser.py", line 144, in parse_statement
    self.fail_unknown_tag(token.value, token.lineno)
  File "/home/minas/microblog/flask/lib/python3.5/site-packages/jinja2/parser.py", line 97, in fail_unknown_tag
    return self._fail_ut_eof(name, self._end_token_stack, lineno)
  File "/home/minas/microblog/flask/lib/python3.5/site-packages/jinja2/parser.py", line 90, in _fail_ut_eof
    self.fail(' '.join(message), lineno)
  File "/home/minas/microblog/flask/lib/python3.5/site-packages/jinja2/parser.py", line 59, in fail
    raise exc(msg, lineno, self.name, self.filename)
jinja2.exceptions.TemplateSyntaxError: Encountered unknown tag 'endfor'. Jinja was looking for the following tags: 'endblock'. The innermost block that needs to be closed is 'block'.
2017-05-01 20:53:09,534 ERROR: Exception on /index [GET] [in /home/minas/microblog/flask/lib/python3.5/site-packages/flask/app.py:1560]
Traceback (most recent call last):
  File "/home/minas/microblog/flask/lib/python3.5/site-packages/flask/app.py", line 1982, in wsgi_app
    response = self.full_dispatch_request()
  File "/home/minas/microblog/flask/lib/python3.5/site-packages/flask/app.py", line 1614, in full_dispatch_request
    rv = self.handle_user_exception(e)
  File "/home/minas/microblog/flask/lib/python3.5/site-packages/flask/app.py", line 1517, in handle_user_exception
    reraise(exc_type, exc_value, tb)
  File "/home/minas/microblog/flask/lib/python3.5/site-packages/flask/_compat.py", line 33, in reraise
    raise value
  File "/home/minas/microblog/flask/lib/python3.5/site-packages/flask/app.py", line 1612, in full_dispatch_request
    rv = self.dispatch_request()
  File "/home/minas/microblog/flask/lib/python3.5/site-packages/flask/app.py", line 1598, in dispatch_request
    return self.view_functions[rule.endpoint](**req.view_args)
  File "/home/minas/microblog/flask/lib/python3.5/site-packages/flask_login/utils.py", line 228, in decorated_view
    return func(*args, **kwargs)
  File "/home/minas/microblog/app/views.py", line 37, in index
    posts=posts)
  File "/home/minas/microblog/flask/lib/python3.5/site-packages/flask/templating.py", line 133, in render_template
    return _render(ctx.app.jinja_env.get_or_select_template(template_name_or_list),
  File "/home/minas/microblog/flask/lib/python3.5/site-packages/jinja2/environment.py", line 869, in get_or_select_template
    return self.get_template(template_name_or_list, parent, globals)
  File "/home/minas/microblog/flask/lib/python3.5/site-packages/jinja2/environment.py", line 830, in get_template
    return self._load_template(name, self.make_globals(globals))
  File "/home/minas/microblog/flask/lib/python3.5/site-packages/jinja2/environment.py", line 804, in _load_template
    template = self.loader.load(self, name, globals)
  File "/home/minas/microblog/flask/lib/python3.5/site-packages/jinja2/loaders.py", line 125, in load
    code = environment.compile(source, name, filename)
  File "/home/minas/microblog/flask/lib/python3.5/site-packages/jinja2/environment.py", line 591, in compile
    self.handle_exception(exc_info, source_hint=source_hint)
  File "/home/minas/microblog/flask/lib/python3.5/site-packages/jinja2/environment.py", line 780, in handle_exception
    reraise(exc_type, exc_value, tb)
  File "/home/minas/microblog/flask/lib/python3.5/site-packages/jinja2/_compat.py", line 37, in reraise
    raise value.with_traceback(tb)
  File "/home/minas/microblog/app/templates/index.html", line 32, in template
    {% endfor %}
  File "/home/minas/microblog/flask/lib/python3.5/site-packages/jinja2/environment.py", line 497, in _parse
    return Parser(self, source, name, encode_filename(filename)).parse()
  File "/home/minas/microblog/flask/lib/python3.5/site-packages/jinja2/parser.py", line 896, in parse
    result = nodes.Template(self.subparse(), lineno=1)
  File "/home/minas/microblog/flask/lib/python3.5/site-packages/jinja2/parser.py", line 878, in subparse
    rv = self.parse_statement()
  File "/home/minas/microblog/flask/lib/python3.5/site-packages/jinja2/parser.py", line 130, in parse_statement
    return getattr(self, 'parse_' + self.stream.current.value)()
  File "/home/minas/microblog/flask/lib/python3.5/site-packages/jinja2/parser.py", line 268, in parse_block
    node.body = self.parse_statements(('name:endblock',), drop_needle=True)
  File "/home/minas/microblog/flask/lib/python3.5/site-packages/jinja2/parser.py", line 165, in parse_statements
    result = self.subparse(end_tokens)
  File "/home/minas/microblog/flask/lib/python3.5/site-packages/jinja2/parser.py", line 878, in subparse
    rv = self.parse_statement()
  File "/home/minas/microblog/flask/lib/python3.5/site-packages/jinja2/parser.py", line 144, in parse_statement
    self.fail_unknown_tag(token.value, token.lineno)
  File "/home/minas/microblog/flask/lib/python3.5/site-packages/jinja2/parser.py", line 97, in fail_unknown_tag
    return self._fail_ut_eof(name, self._end_token_stack, lineno)
  File "/home/minas/microblog/flask/lib/python3.5/site-packages/jinja2/parser.py", line 90, in _fail_ut_eof
    self.fail(' '.join(message), lineno)
  File "/home/minas/microblog/flask/lib/python3.5/site-packages/jinja2/parser.py", line 59, in fail
    raise exc(msg, lineno, self.name, self.filename)
jinja2.exceptions.TemplateSyntaxError: Encountered unknown tag 'endfor'. Jinja was looking for the following tags: 'endblock'. The innermost block that needs to be closed is 'block'.
2017-05-01 20:53:40,597 INFO: microblog startup [in /home/minas/microblog/app/__init__.py:24]
2017-05-01 20:53:45,307 INFO: microblog startup [in /home/minas/microblog/app/__init__.py:24]
2017-05-01 20:53:50,625 ERROR: Exception on /index [GET] [in /home/minas/microblog/flask/lib/python3.5/site-packages/flask/app.py:1560]
Traceback (most recent call last):
  File "/home/minas/microblog/flask/lib/python3.5/site-packages/flask/app.py", line 1982, in wsgi_app
    response = self.full_dispatch_request()
  File "/home/minas/microblog/flask/lib/python3.5/site-packages/flask/app.py", line 1614, in full_dispatch_request
    rv = self.handle_user_exception(e)
  File "/home/minas/microblog/flask/lib/python3.5/site-packages/flask/app.py", line 1517, in handle_user_exception
    reraise(exc_type, exc_value, tb)
  File "/home/minas/microblog/flask/lib/python3.5/site-packages/flask/_compat.py", line 33, in reraise
    raise value
  File "/home/minas/microblog/flask/lib/python3.5/site-packages/flask/app.py", line 1612, in full_dispatch_request
    rv = self.dispatch_request()
  File "/home/minas/microblog/flask/lib/python3.5/site-packages/flask/app.py", line 1598, in dispatch_request
    return self.view_functions[rule.endpoint](**req.view_args)
  File "/home/minas/microblog/flask/lib/python3.5/site-packages/flask_login/utils.py", line 228, in decorated_view
    return func(*args, **kwargs)
  File "/home/minas/microblog/app/views.py", line 37, in index
    posts=posts)
  File "/home/minas/microblog/flask/lib/python3.5/site-packages/flask/templating.py", line 133, in render_template
    return _render(ctx.app.jinja_env.get_or_select_template(template_name_or_list),
  File "/home/minas/microblog/flask/lib/python3.5/site-packages/jinja2/environment.py", line 869, in get_or_select_template
    return self.get_template(template_name_or_list, parent, globals)
  File "/home/minas/microblog/flask/lib/python3.5/site-packages/jinja2/environment.py", line 830, in get_template
    return self._load_template(name, self.make_globals(globals))
  File "/home/minas/microblog/flask/lib/python3.5/site-packages/jinja2/environment.py", line 804, in _load_template
    template = self.loader.load(self, name, globals)
  File "/home/minas/microblog/flask/lib/python3.5/site-packages/jinja2/loaders.py", line 125, in load
    code = environment.compile(source, name, filename)
  File "/home/minas/microblog/flask/lib/python3.5/site-packages/jinja2/environment.py", line 591, in compile
    self.handle_exception(exc_info, source_hint=source_hint)
  File "/home/minas/microblog/flask/lib/python3.5/site-packages/jinja2/environment.py", line 780, in handle_exception
    reraise(exc_type, exc_value, tb)
  File "/home/minas/microblog/flask/lib/python3.5/site-packages/jinja2/_compat.py", line 37, in reraise
    raise value.with_traceback(tb)
  File "/home/minas/microblog/app/templates/index.html", line 32, in template
    {% endfor %}
  File "/home/minas/microblog/flask/lib/python3.5/site-packages/jinja2/environment.py", line 497, in _parse
    return Parser(self, source, name, encode_filename(filename)).parse()
  File "/home/minas/microblog/flask/lib/python3.5/site-packages/jinja2/parser.py", line 896, in parse
    result = nodes.Template(self.subparse(), lineno=1)
  File "/home/minas/microblog/flask/lib/python3.5/site-packages/jinja2/parser.py", line 878, in subparse
    rv = self.parse_statement()
  File "/home/minas/microblog/flask/lib/python3.5/site-packages/jinja2/parser.py", line 130, in parse_statement
    return getattr(self, 'parse_' + self.stream.current.value)()
  File "/home/minas/microblog/flask/lib/python3.5/site-packages/jinja2/parser.py", line 268, in parse_block
    node.body = self.parse_statements(('name:endblock',), drop_needle=True)
  File "/home/minas/microblog/flask/lib/python3.5/site-packages/jinja2/parser.py", line 165, in parse_statements
    result = self.subparse(end_tokens)
  File "/home/minas/microblog/flask/lib/python3.5/site-packages/jinja2/parser.py", line 878, in subparse
    rv = self.parse_statement()
  File "/home/minas/microblog/flask/lib/python3.5/site-packages/jinja2/parser.py", line 144, in parse_statement
    self.fail_unknown_tag(token.value, token.lineno)
  File "/home/minas/microblog/flask/lib/python3.5/site-packages/jinja2/parser.py", line 97, in fail_unknown_tag
    return self._fail_ut_eof(name, self._end_token_stack, lineno)
  File "/home/minas/microblog/flask/lib/python3.5/site-packages/jinja2/parser.py", line 90, in _fail_ut_eof
    self.fail(' '.join(message), lineno)
  File "/home/minas/microblog/flask/lib/python3.5/site-packages/jinja2/parser.py", line 59, in fail
    raise exc(msg, lineno, self.name, self.filename)
jinja2.exceptions.TemplateSyntaxError: Encountered unknown tag 'endfor'. Jinja was looking for the following tags: 'endblock'. The innermost block that needs to be closed is 'block'.
2017-05-01 20:53:52,876 ERROR: Exception on /index [GET] [in /home/minas/microblog/flask/lib/python3.5/site-packages/flask/app.py:1560]
Traceback (most recent call last):
  File "/home/minas/microblog/flask/lib/python3.5/site-packages/flask/app.py", line 1982, in wsgi_app
    response = self.full_dispatch_request()
  File "/home/minas/microblog/flask/lib/python3.5/site-packages/flask/app.py", line 1614, in full_dispatch_request
    rv = self.handle_user_exception(e)
  File "/home/minas/microblog/flask/lib/python3.5/site-packages/flask/app.py", line 1517, in handle_user_exception
    reraise(exc_type, exc_value, tb)
  File "/home/minas/microblog/flask/lib/python3.5/site-packages/flask/_compat.py", line 33, in reraise
    raise value
  File "/home/minas/microblog/flask/lib/python3.5/site-packages/flask/app.py", line 1612, in full_dispatch_request
    rv = self.dispatch_request()
  File "/home/minas/microblog/flask/lib/python3.5/site-packages/flask/app.py", line 1598, in dispatch_request
    return self.view_functions[rule.endpoint](**req.view_args)
  File "/home/minas/microblog/flask/lib/python3.5/site-packages/flask_login/utils.py", line 228, in decorated_view
    return func(*args, **kwargs)
  File "/home/minas/microblog/app/views.py", line 37, in index
    posts=posts)
  File "/home/minas/microblog/flask/lib/python3.5/site-packages/flask/templating.py", line 133, in render_template
    return _render(ctx.app.jinja_env.get_or_select_template(template_name_or_list),
  File "/home/minas/microblog/flask/lib/python3.5/site-packages/jinja2/environment.py", line 869, in get_or_select_template
    return self.get_template(template_name_or_list, parent, globals)
  File "/home/minas/microblog/flask/lib/python3.5/site-packages/jinja2/environment.py", line 830, in get_template
    return self._load_template(name, self.make_globals(globals))
  File "/home/minas/microblog/flask/lib/python3.5/site-packages/jinja2/environment.py", line 804, in _load_template
    template = self.loader.load(self, name, globals)
  File "/home/minas/microblog/flask/lib/python3.5/site-packages/jinja2/loaders.py", line 125, in load
    code = environment.compile(source, name, filename)
  File "/home/minas/microblog/flask/lib/python3.5/site-packages/jinja2/environment.py", line 591, in compile
    self.handle_exception(exc_info, source_hint=source_hint)
  File "/home/minas/microblog/flask/lib/python3.5/site-packages/jinja2/environment.py", line 780, in handle_exception
    reraise(exc_type, exc_value, tb)
  File "/home/minas/microblog/flask/lib/python3.5/site-packages/jinja2/_compat.py", line 37, in reraise
    raise value.with_traceback(tb)
  File "/home/minas/microblog/app/templates/index.html", line 32, in template
    {% endfor %}
  File "/home/minas/microblog/flask/lib/python3.5/site-packages/jinja2/environment.py", line 497, in _parse
    return Parser(self, source, name, encode_filename(filename)).parse()
  File "/home/minas/microblog/flask/lib/python3.5/site-packages/jinja2/parser.py", line 896, in parse
    result = nodes.Template(self.subparse(), lineno=1)
  File "/home/minas/microblog/flask/lib/python3.5/site-packages/jinja2/parser.py", line 878, in subparse
    rv = self.parse_statement()
  File "/home/minas/microblog/flask/lib/python3.5/site-packages/jinja2/parser.py", line 130, in parse_statement
    return getattr(self, 'parse_' + self.stream.current.value)()
  File "/home/minas/microblog/flask/lib/python3.5/site-packages/jinja2/parser.py", line 268, in parse_block
    node.body = self.parse_statements(('name:endblock',), drop_needle=True)
  File "/home/minas/microblog/flask/lib/python3.5/site-packages/jinja2/parser.py", line 165, in parse_statements
    result = self.subparse(end_tokens)
  File "/home/minas/microblog/flask/lib/python3.5/site-packages/jinja2/parser.py", line 878, in subparse
    rv = self.parse_statement()
  File "/home/minas/microblog/flask/lib/python3.5/site-packages/jinja2/parser.py", line 144, in parse_statement
    self.fail_unknown_tag(token.value, token.lineno)
  File "/home/minas/microblog/flask/lib/python3.5/site-packages/jinja2/parser.py", line 97, in fail_unknown_tag
    return self._fail_ut_eof(name, self._end_token_stack, lineno)
  File "/home/minas/microblog/flask/lib/python3.5/site-packages/jinja2/parser.py", line 90, in _fail_ut_eof
    self.fail(' '.join(message), lineno)
  File "/home/minas/microblog/flask/lib/python3.5/site-packages/jinja2/parser.py", line 59, in fail
    raise exc(msg, lineno, self.name, self.filename)
jinja2.exceptions.TemplateSyntaxError: Encountered unknown tag 'endfor'. Jinja was looking for the following tags: 'endblock'. The innermost block that needs to be closed is 'block'.
2017-05-01 20:54:11,931 INFO: microblog startup [in /home/minas/microblog/app/__init__.py:24]
2017-05-01 20:54:14,346 INFO: microblog startup [in /home/minas/microblog/app/__init__.py:24]
2017-05-01 21:10:26,686 INFO: microblog startup [in /home/minas/microblog/app/__init__.py:24]
2017-05-01 21:10:56,896 INFO: microblog startup [in /home/minas/microblog/app/__init__.py:24]
2017-05-01 21:12:05,728 INFO: microblog startup [in /home/minas/microblog/app/__init__.py:24]
2017-05-02 00:10:20,680 INFO: microblog startup [in /home/minas/microblog/app/__init__.py:24]
2017-05-02 00:11:35,583 INFO: microblog startup [in /home/minas/microblog/app/__init__.py:24]
2017-05-02 00:17:17,796 INFO: microblog startup [in /home/minas/microblog/app/__init__.py:24]
2017-05-02 00:17:37,095 INFO: microblog startup [in /home/minas/microblog/app/__init__.py:24]
2017-05-02 00:37:08,812 INFO: microblog startup [in /home/minas/microblog/app/__init__.py:24]
2017-05-02 00:42:07,616 INFO: microblog startup [in /home/minas/microblog/app/__init__.py:24]
2017-05-02 00:43:14,586 INFO: microblog startup [in /home/minas/microblog/app/__init__.py:24]
2017-05-02 00:50:03,964 INFO: microblog startup [in /home/minas/microblog/app/__init__.py:24]
2017-05-02 01:01:26,020 INFO: microblog startup [in /home/minas/microblog/app/__init__.py:24]
2017-05-02 01:01:48,395 INFO: microblog startup [in /home/minas/microblog/app/__init__.py:24]
2017-05-02 01:07:17,058 INFO: microblog startup [in /home/minas/microblog/app/__init__.py:24]
2017-05-02 01:07:38,580 INFO: microblog startup [in /home/minas/microblog/app/__init__.py:24]
2017-05-02 01:12:32,102 INFO: microblog startup [in /home/minas/microblog/app/__init__.py:39]
2017-05-02 01:16:13,014 INFO: microblog startup [in /home/minas/microblog/app/__init__.py:39]
2017-05-02 01:16:24,811 INFO: microblog startup [in /home/minas/microblog/app/__init__.py:39]
2017-05-02 01:16:54,950 ERROR: Exception on /search_results/post [GET] [in /home/minas/microblog/flask/lib/python3.5/site-packages/flask/app.py:1423]
Traceback (most recent call last):
  File "/home/minas/microblog/flask/lib/python3.5/site-packages/flask/app.py", line 1817, in wsgi_app
    response = self.full_dispatch_request()
  File "/home/minas/microblog/flask/lib/python3.5/site-packages/flask/app.py", line 1477, in full_dispatch_request
    rv = self.handle_user_exception(e)
  File "/home/minas/microblog/flask/lib/python3.5/site-packages/flask/app.py", line 1381, in handle_user_exception
    reraise(exc_type, exc_value, tb)
  File "/home/minas/microblog/flask/lib/python3.5/site-packages/flask/_compat.py", line 33, in reraise
    raise value
  File "/home/minas/microblog/flask/lib/python3.5/site-packages/flask/app.py", line 1475, in full_dispatch_request
    rv = self.dispatch_request()
  File "/home/minas/microblog/flask/lib/python3.5/site-packages/flask/app.py", line 1461, in dispatch_request
    return self.view_functions[rule.endpoint](**req.view_args)
  File "/home/minas/microblog/flask/lib/python3.5/site-packages/flask_login/utils.py", line 228, in decorated_view
    return func(*args, **kwargs)
  File "/home/minas/microblog/app/views.py", line 184, in search_results
    results = Post.query.whoosh_search(query, MAX_SEARCH_RESULTS).all()
AttributeError: 'BaseQuery' object has no attribute 'whoosh_search'
2017-05-02 01:17:30,831 ERROR: Exception on /search_results/second [GET] [in /home/minas/microblog/flask/lib/python3.5/site-packages/flask/app.py:1423]
Traceback (most recent call last):
  File "/home/minas/microblog/flask/lib/python3.5/site-packages/flask/app.py", line 1817, in wsgi_app
    response = self.full_dispatch_request()
  File "/home/minas/microblog/flask/lib/python3.5/site-packages/flask/app.py", line 1477, in full_dispatch_request
    rv = self.handle_user_exception(e)
  File "/home/minas/microblog/flask/lib/python3.5/site-packages/flask/app.py", line 1381, in handle_user_exception
    reraise(exc_type, exc_value, tb)
  File "/home/minas/microblog/flask/lib/python3.5/site-packages/flask/_compat.py", line 33, in reraise
    raise value
  File "/home/minas/microblog/flask/lib/python3.5/site-packages/flask/app.py", line 1475, in full_dispatch_request
    rv = self.dispatch_request()
  File "/home/minas/microblog/flask/lib/python3.5/site-packages/flask/app.py", line 1461, in dispatch_request
    return self.view_functions[rule.endpoint](**req.view_args)
  File "/home/minas/microblog/flask/lib/python3.5/site-packages/flask_login/utils.py", line 228, in decorated_view
    return func(*args, **kwargs)
  File "/home/minas/microblog/app/views.py", line 184, in search_results
    results = Post.query.whoosh_search(query, MAX_SEARCH_RESULTS).all()
AttributeError: 'BaseQuery' object has no attribute 'whoosh_search'
2017-05-07 22:56:59,891 INFO: microblog startup [in /home/minas/microblog/app/__init__.py:39]
2017-05-07 22:57:37,789 ERROR: Exception on /search_results/post [GET] [in /home/minas/microblog/flask/lib/python3.5/site-packages/flask/app.py:1423]
Traceback (most recent call last):
  File "/home/minas/microblog/flask/lib/python3.5/site-packages/flask/app.py", line 1817, in wsgi_app
    response = self.full_dispatch_request()
  File "/home/minas/microblog/flask/lib/python3.5/site-packages/flask/app.py", line 1477, in full_dispatch_request
    rv = self.handle_user_exception(e)
  File "/home/minas/microblog/flask/lib/python3.5/site-packages/flask/app.py", line 1381, in handle_user_exception
    reraise(exc_type, exc_value, tb)
  File "/home/minas/microblog/flask/lib/python3.5/site-packages/flask/_compat.py", line 33, in reraise
    raise value
  File "/home/minas/microblog/flask/lib/python3.5/site-packages/flask/app.py", line 1475, in full_dispatch_request
    rv = self.dispatch_request()
  File "/home/minas/microblog/flask/lib/python3.5/site-packages/flask/app.py", line 1461, in dispatch_request
    return self.view_functions[rule.endpoint](**req.view_args)
  File "/home/minas/microblog/flask/lib/python3.5/site-packages/flask_login/utils.py", line 228, in decorated_view
    return func(*args, **kwargs)
  File "/home/minas/microblog/app/views.py", line 184, in search_results
    results = Post.query.whoosh_search(query, MAX_SEARCH_RESULTS).all()
AttributeError: 'BaseQuery' object has no attribute 'whoosh_search'
2017-05-09 19:37:55,426 INFO: microblog startup [in /home/minas/microblog/app/__init__.py:39]
2017-05-09 19:41:31,389 ERROR: Exception on /search_results/post [GET] [in /home/minas/microblog/flask/lib/python3.5/site-packages/flask/app.py:1423]
Traceback (most recent call last):
  File "/home/minas/microblog/flask/lib/python3.5/site-packages/flask/app.py", line 1817, in wsgi_app
    response = self.full_dispatch_request()
  File "/home/minas/microblog/flask/lib/python3.5/site-packages/flask/app.py", line 1477, in full_dispatch_request
    rv = self.handle_user_exception(e)
  File "/home/minas/microblog/flask/lib/python3.5/site-packages/flask/app.py", line 1381, in handle_user_exception
    reraise(exc_type, exc_value, tb)
  File "/home/minas/microblog/flask/lib/python3.5/site-packages/flask/_compat.py", line 33, in reraise
    raise value
  File "/home/minas/microblog/flask/lib/python3.5/site-packages/flask/app.py", line 1475, in full_dispatch_request
    rv = self.dispatch_request()
  File "/home/minas/microblog/flask/lib/python3.5/site-packages/flask/app.py", line 1461, in dispatch_request
    return self.view_functions[rule.endpoint](**req.view_args)
  File "/home/minas/microblog/flask/lib/python3.5/site-packages/flask_login/utils.py", line 228, in decorated_view
    return func(*args, **kwargs)
  File "/home/minas/microblog/app/views.py", line 184, in search_results
    results = Post.query.whoosh_search(query, MAX_SEARCH_RESULTS).all()
AttributeError: 'BaseQuery' object has no attribute 'whoosh_search'
